2019-12-10 12:45:15,221 ERROR: Exception on /explore [GET] [in C:\Users\dylmp\scoop\apps\python\current\lib\site-packages\flask\app.py:1890]
Traceback (most recent call last):
  File "C:\Users\dylmp\scoop\apps\python\current\lib\site-packages\flask\app.py", line 2446, in wsgi_app
    response = self.full_dispatch_request()
  File "C:\Users\dylmp\scoop\apps\python\current\lib\site-packages\flask\app.py", line 1951, in full_dispatch_request
    rv = self.handle_user_exception(e)
  File "C:\Users\dylmp\scoop\apps\python\current\lib\site-packages\flask\app.py", line 1820, in handle_user_exception
    reraise(exc_type, exc_value, tb)
  File "C:\Users\dylmp\scoop\apps\python\current\lib\site-packages\flask\_compat.py", line 39, in reraise
    raise value
  File "C:\Users\dylmp\scoop\apps\python\current\lib\site-packages\flask\app.py", line 1947, in full_dispatch_request
    rv = self.preprocess_request()
  File "C:\Users\dylmp\scoop\apps\python\current\lib\site-packages\flask\app.py", line 2241, in preprocess_request
    rv = func()
  File "C:\Users\dylmp\CodeProjects\exampleblog\app\routes.py", line 90, in before_request
    g.locale = str(get_locale())
NameError: name 'get_locale' is not defined
2019-12-10 12:45:15,499 ERROR: Exception on /favicon.ico [GET] [in C:\Users\dylmp\scoop\apps\python\current\lib\site-packages\flask\app.py:1890]
Traceback (most recent call last):
  File "C:\Users\dylmp\scoop\apps\python\current\lib\site-packages\flask\app.py", line 2446, in wsgi_app
    response = self.full_dispatch_request()
  File "C:\Users\dylmp\scoop\apps\python\current\lib\site-packages\flask\app.py", line 1951, in full_dispatch_request
    rv = self.handle_user_exception(e)
  File "C:\Users\dylmp\scoop\apps\python\current\lib\site-packages\flask\app.py", line 1820, in handle_user_exception
    reraise(exc_type, exc_value, tb)
  File "C:\Users\dylmp\scoop\apps\python\current\lib\site-packages\flask\_compat.py", line 39, in reraise
    raise value
  File "C:\Users\dylmp\scoop\apps\python\current\lib\site-packages\flask\app.py", line 1947, in full_dispatch_request
    rv = self.preprocess_request()
  File "C:\Users\dylmp\scoop\apps\python\current\lib\site-packages\flask\app.py", line 2241, in preprocess_request
    rv = func()
  File "C:\Users\dylmp\CodeProjects\exampleblog\app\routes.py", line 90, in before_request
    g.locale = str(get_locale())
NameError: name 'get_locale' is not defined
2019-12-10 12:46:45,822 INFO: Microblog startup [in C:\Users\dylmp\CodeProjects\exampleblog\app\__init__.py:53]
2019-12-10 12:46:50,637 ERROR: Exception on /explore [GET] [in C:\Users\dylmp\scoop\apps\python\current\lib\site-packages\flask\app.py:1890]
Traceback (most recent call last):
  File "C:\Users\dylmp\scoop\apps\python\current\lib\site-packages\flask\app.py", line 2446, in wsgi_app
    response = self.full_dispatch_request()
  File "C:\Users\dylmp\scoop\apps\python\current\lib\site-packages\flask\app.py", line 1951, in full_dispatch_request
    rv = self.handle_user_exception(e)
  File "C:\Users\dylmp\scoop\apps\python\current\lib\site-packages\flask\app.py", line 1820, in handle_user_exception
    reraise(exc_type, exc_value, tb)
  File "C:\Users\dylmp\scoop\apps\python\current\lib\site-packages\flask\_compat.py", line 39, in reraise
    raise value
  File "C:\Users\dylmp\scoop\apps\python\current\lib\site-packages\flask\app.py", line 1947, in full_dispatch_request
    rv = self.preprocess_request()
  File "C:\Users\dylmp\scoop\apps\python\current\lib\site-packages\flask\app.py", line 2241, in preprocess_request
    rv = func()
  File "C:\Users\dylmp\CodeProjects\exampleblog\app\routes.py", line 90, in before_request
    g.locale = str(get_locale())
NameError: name 'get_locale' is not defined
2019-12-10 12:46:50,963 ERROR: Exception on /favicon.ico [GET] [in C:\Users\dylmp\scoop\apps\python\current\lib\site-packages\flask\app.py:1890]
Traceback (most recent call last):
  File "C:\Users\dylmp\scoop\apps\python\current\lib\site-packages\flask\app.py", line 2446, in wsgi_app
    response = self.full_dispatch_request()
  File "C:\Users\dylmp\scoop\apps\python\current\lib\site-packages\flask\app.py", line 1951, in full_dispatch_request
    rv = self.handle_user_exception(e)
  File "C:\Users\dylmp\scoop\apps\python\current\lib\site-packages\flask\app.py", line 1820, in handle_user_exception
    reraise(exc_type, exc_value, tb)
  File "C:\Users\dylmp\scoop\apps\python\current\lib\site-packages\flask\_compat.py", line 39, in reraise
    raise value
  File "C:\Users\dylmp\scoop\apps\python\current\lib\site-packages\flask\app.py", line 1947, in full_dispatch_request
    rv = self.preprocess_request()
  File "C:\Users\dylmp\scoop\apps\python\current\lib\site-packages\flask\app.py", line 2241, in preprocess_request
    rv = func()
  File "C:\Users\dylmp\CodeProjects\exampleblog\app\routes.py", line 90, in before_request
    g.locale = str(get_locale())
NameError: name 'get_locale' is not defined
2019-12-10 12:48:21,194 INFO: Microblog startup [in C:\Users\dylmp\CodeProjects\exampleblog\app\__init__.py:53]
2019-12-10 12:48:26,128 ERROR: Exception on /explore [GET] [in C:\Users\dylmp\scoop\apps\python\current\lib\site-packages\flask\app.py:1890]
Traceback (most recent call last):
  File "C:\Users\dylmp\scoop\apps\python\current\lib\site-packages\flask\app.py", line 2446, in wsgi_app
    response = self.full_dispatch_request()
  File "C:\Users\dylmp\scoop\apps\python\current\lib\site-packages\flask\app.py", line 1951, in full_dispatch_request
    rv = self.handle_user_exception(e)
  File "C:\Users\dylmp\scoop\apps\python\current\lib\site-packages\flask\app.py", line 1820, in handle_user_exception
    reraise(exc_type, exc_value, tb)
  File "C:\Users\dylmp\scoop\apps\python\current\lib\site-packages\flask\_compat.py", line 39, in reraise
    raise value
  File "C:\Users\dylmp\scoop\apps\python\current\lib\site-packages\flask\app.py", line 1947, in full_dispatch_request
    rv = self.preprocess_request()
  File "C:\Users\dylmp\scoop\apps\python\current\lib\site-packages\flask\app.py", line 2241, in preprocess_request
    rv = func()
  File "C:\Users\dylmp\CodeProjects\exampleblog\app\routes.py", line 90, in before_request
    g.locale = str(get_locale())
NameError: name 'get_locale' is not defined
2019-12-10 12:48:26,463 ERROR: Exception on /favicon.ico [GET] [in C:\Users\dylmp\scoop\apps\python\current\lib\site-packages\flask\app.py:1890]
Traceback (most recent call last):
  File "C:\Users\dylmp\scoop\apps\python\current\lib\site-packages\flask\app.py", line 2446, in wsgi_app
    response = self.full_dispatch_request()
  File "C:\Users\dylmp\scoop\apps\python\current\lib\site-packages\flask\app.py", line 1951, in full_dispatch_request
    rv = self.handle_user_exception(e)
  File "C:\Users\dylmp\scoop\apps\python\current\lib\site-packages\flask\app.py", line 1820, in handle_user_exception
    reraise(exc_type, exc_value, tb)
  File "C:\Users\dylmp\scoop\apps\python\current\lib\site-packages\flask\_compat.py", line 39, in reraise
    raise value
  File "C:\Users\dylmp\scoop\apps\python\current\lib\site-packages\flask\app.py", line 1947, in full_dispatch_request
    rv = self.preprocess_request()
  File "C:\Users\dylmp\scoop\apps\python\current\lib\site-packages\flask\app.py", line 2241, in preprocess_request
    rv = func()
  File "C:\Users\dylmp\CodeProjects\exampleblog\app\routes.py", line 90, in before_request
    g.locale = str(get_locale())
NameError: name 'get_locale' is not defined
2019-12-10 12:48:28,664 ERROR: Exception on /index [GET] [in C:\Users\dylmp\scoop\apps\python\current\lib\site-packages\flask\app.py:1890]
Traceback (most recent call last):
  File "C:\Users\dylmp\scoop\apps\python\current\lib\site-packages\flask\app.py", line 2446, in wsgi_app
    response = self.full_dispatch_request()
  File "C:\Users\dylmp\scoop\apps\python\current\lib\site-packages\flask\app.py", line 1951, in full_dispatch_request
    rv = self.handle_user_exception(e)
  File "C:\Users\dylmp\scoop\apps\python\current\lib\site-packages\flask\app.py", line 1820, in handle_user_exception
    reraise(exc_type, exc_value, tb)
  File "C:\Users\dylmp\scoop\apps\python\current\lib\site-packages\flask\_compat.py", line 39, in reraise
    raise value
  File "C:\Users\dylmp\scoop\apps\python\current\lib\site-packages\flask\app.py", line 1947, in full_dispatch_request
    rv = self.preprocess_request()
  File "C:\Users\dylmp\scoop\apps\python\current\lib\site-packages\flask\app.py", line 2241, in preprocess_request
    rv = func()
  File "C:\Users\dylmp\CodeProjects\exampleblog\app\routes.py", line 90, in before_request
    g.locale = str(get_locale())
NameError: name 'get_locale' is not defined
2019-12-10 12:48:28,917 ERROR: Exception on /favicon.ico [GET] [in C:\Users\dylmp\scoop\apps\python\current\lib\site-packages\flask\app.py:1890]
Traceback (most recent call last):
  File "C:\Users\dylmp\scoop\apps\python\current\lib\site-packages\flask\app.py", line 2446, in wsgi_app
    response = self.full_dispatch_request()
  File "C:\Users\dylmp\scoop\apps\python\current\lib\site-packages\flask\app.py", line 1951, in full_dispatch_request
    rv = self.handle_user_exception(e)
  File "C:\Users\dylmp\scoop\apps\python\current\lib\site-packages\flask\app.py", line 1820, in handle_user_exception
    reraise(exc_type, exc_value, tb)
  File "C:\Users\dylmp\scoop\apps\python\current\lib\site-packages\flask\_compat.py", line 39, in reraise
    raise value
  File "C:\Users\dylmp\scoop\apps\python\current\lib\site-packages\flask\app.py", line 1947, in full_dispatch_request
    rv = self.preprocess_request()
  File "C:\Users\dylmp\scoop\apps\python\current\lib\site-packages\flask\app.py", line 2241, in preprocess_request
    rv = func()
  File "C:\Users\dylmp\CodeProjects\exampleblog\app\routes.py", line 90, in before_request
    g.locale = str(get_locale())
NameError: name 'get_locale' is not defined
2019-12-10 12:49:58,242 INFO: Microblog startup [in C:\Users\dylmp\CodeProjects\exampleblog\app\__init__.py:55]
