2019-12-10 12:50:02,190 ERROR: Exception on /index [GET] [in C:\Users\dylmp\scoop\apps\python\current\lib\site-packages\flask\app.py:1890]
Traceback (most recent call last):
  File "C:\Users\dylmp\scoop\apps\python\current\lib\site-packages\flask\app.py", line 2446, in wsgi_app
    response = self.full_dispatch_request()
  File "C:\Users\dylmp\scoop\apps\python\current\lib\site-packages\flask\app.py", line 1951, in full_dispatch_request
    rv = self.handle_user_exception(e)
  File "C:\Users\dylmp\scoop\apps\python\current\lib\site-packages\flask\app.py", line 1820, in handle_user_exception
    reraise(exc_type, exc_value, tb)
  File "C:\Users\dylmp\scoop\apps\python\current\lib\site-packages\flask\_compat.py", line 39, in reraise
    raise value
  File "C:\Users\dylmp\scoop\apps\python\current\lib\site-packages\flask\app.py", line 1947, in full_dispatch_request
    rv = self.preprocess_request()
  File "C:\Users\dylmp\scoop\apps\python\current\lib\site-packages\flask\app.py", line 2241, in preprocess_request
    rv = func()
  File "C:\Users\dylmp\CodeProjects\exampleblog\app\routes.py", line 90, in before_request
    g.locale = str(get_locale())
NameError: name 'get_locale' is not defined
2019-12-10 12:50:02,537 ERROR: Exception on /favicon.ico [GET] [in C:\Users\dylmp\scoop\apps\python\current\lib\site-packages\flask\app.py:1890]
Traceback (most recent call last):
  File "C:\Users\dylmp\scoop\apps\python\current\lib\site-packages\flask\app.py", line 2446, in wsgi_app
    response = self.full_dispatch_request()
  File "C:\Users\dylmp\scoop\apps\python\current\lib\site-packages\flask\app.py", line 1951, in full_dispatch_request
    rv = self.handle_user_exception(e)
  File "C:\Users\dylmp\scoop\apps\python\current\lib\site-packages\flask\app.py", line 1820, in handle_user_exception
    reraise(exc_type, exc_value, tb)
  File "C:\Users\dylmp\scoop\apps\python\current\lib\site-packages\flask\_compat.py", line 39, in reraise
    raise value
  File "C:\Users\dylmp\scoop\apps\python\current\lib\site-packages\flask\app.py", line 1947, in full_dispatch_request
    rv = self.preprocess_request()
  File "C:\Users\dylmp\scoop\apps\python\current\lib\site-packages\flask\app.py", line 2241, in preprocess_request
    rv = func()
  File "C:\Users\dylmp\CodeProjects\exampleblog\app\routes.py", line 90, in before_request
    g.locale = str(get_locale())
NameError: name 'get_locale' is not defined
2019-12-10 12:51:31,063 INFO: Microblog startup [in C:\Users\dylmp\CodeProjects\exampleblog\app\__init__.py:55]
2019-12-10 12:51:35,437 ERROR: Exception on /index [GET] [in C:\Users\dylmp\scoop\apps\python\current\lib\site-packages\flask\app.py:1890]
Traceback (most recent call last):
  File "C:\Users\dylmp\scoop\apps\python\current\lib\site-packages\flask\app.py", line 2446, in wsgi_app
    response = self.full_dispatch_request()
  File "C:\Users\dylmp\scoop\apps\python\current\lib\site-packages\flask\app.py", line 1951, in full_dispatch_request
    rv = self.handle_user_exception(e)
  File "C:\Users\dylmp\scoop\apps\python\current\lib\site-packages\flask\app.py", line 1820, in handle_user_exception
    reraise(exc_type, exc_value, tb)
  File "C:\Users\dylmp\scoop\apps\python\current\lib\site-packages\flask\_compat.py", line 39, in reraise
    raise value
  File "C:\Users\dylmp\scoop\apps\python\current\lib\site-packages\flask\app.py", line 1947, in full_dispatch_request
    rv = self.preprocess_request()
  File "C:\Users\dylmp\scoop\apps\python\current\lib\site-packages\flask\app.py", line 2241, in preprocess_request
    rv = func()
  File "C:\Users\dylmp\CodeProjects\exampleblog\app\routes.py", line 90, in before_request
    g.locale = str(get_locale())
NameError: name 'get_locale' is not defined
2019-12-10 12:51:35,783 ERROR: Exception on /favicon.ico [GET] [in C:\Users\dylmp\scoop\apps\python\current\lib\site-packages\flask\app.py:1890]
Traceback (most recent call last):
  File "C:\Users\dylmp\scoop\apps\python\current\lib\site-packages\flask\app.py", line 2446, in wsgi_app
    response = self.full_dispatch_request()
  File "C:\Users\dylmp\scoop\apps\python\current\lib\site-packages\flask\app.py", line 1951, in full_dispatch_request
    rv = self.handle_user_exception(e)
  File "C:\Users\dylmp\scoop\apps\python\current\lib\site-packages\flask\app.py", line 1820, in handle_user_exception
    reraise(exc_type, exc_value, tb)
  File "C:\Users\dylmp\scoop\apps\python\current\lib\site-packages\flask\_compat.py", line 39, in reraise
    raise value
  File "C:\Users\dylmp\scoop\apps\python\current\lib\site-packages\flask\app.py", line 1947, in full_dispatch_request
    rv = self.preprocess_request()
  File "C:\Users\dylmp\scoop\apps\python\current\lib\site-packages\flask\app.py", line 2241, in preprocess_request
    rv = func()
  File "C:\Users\dylmp\CodeProjects\exampleblog\app\routes.py", line 90, in before_request
    g.locale = str(get_locale())
NameError: name 'get_locale' is not defined
2019-12-10 12:53:36,242 INFO: Microblog startup [in C:\Users\dylmp\CodeProjects\exampleblog\app\__init__.py:55]
2019-12-10 12:53:39,725 ERROR: Exception on /index [GET] [in C:\Users\dylmp\scoop\apps\python\current\lib\site-packages\flask\app.py:1890]
Traceback (most recent call last):
  File "C:\Users\dylmp\scoop\apps\python\current\lib\site-packages\flask\app.py", line 2446, in wsgi_app
    response = self.full_dispatch_request()
  File "C:\Users\dylmp\scoop\apps\python\current\lib\site-packages\flask\app.py", line 1951, in full_dispatch_request
    rv = self.handle_user_exception(e)
  File "C:\Users\dylmp\scoop\apps\python\current\lib\site-packages\flask\app.py", line 1820, in handle_user_exception
    reraise(exc_type, exc_value, tb)
  File "C:\Users\dylmp\scoop\apps\python\current\lib\site-packages\flask\_compat.py", line 39, in reraise
    raise value
  File "C:\Users\dylmp\scoop\apps\python\current\lib\site-packages\flask\app.py", line 1947, in full_dispatch_request
    rv = self.preprocess_request()
  File "C:\Users\dylmp\scoop\apps\python\current\lib\site-packages\flask\app.py", line 2241, in preprocess_request
    rv = func()
  File "C:\Users\dylmp\CodeProjects\exampleblog\app\routes.py", line 91, in before_request
    g.locale = str(get_locale())
  File "C:\Users\dylmp\scoop\apps\python\current\lib\site-packages\flask_babel\__init__.py", line 257, in get_locale
    rv = babel.locale_selector_func()
  File "C:\Users\dylmp\CodeProjects\exampleblog\app\__init__.py", line 59, in get_locale
    return request.accept_languages.best_match(app.config['LANGUAGES'])
NameError: name 'request' is not defined
2019-12-10 12:53:40,055 ERROR: Exception on /favicon.ico [GET] [in C:\Users\dylmp\scoop\apps\python\current\lib\site-packages\flask\app.py:1890]
Traceback (most recent call last):
  File "C:\Users\dylmp\scoop\apps\python\current\lib\site-packages\flask\app.py", line 2446, in wsgi_app
    response = self.full_dispatch_request()
  File "C:\Users\dylmp\scoop\apps\python\current\lib\site-packages\flask\app.py", line 1951, in full_dispatch_request
    rv = self.handle_user_exception(e)
  File "C:\Users\dylmp\scoop\apps\python\current\lib\site-packages\flask\app.py", line 1820, in handle_user_exception
    reraise(exc_type, exc_value, tb)
  File "C:\Users\dylmp\scoop\apps\python\current\lib\site-packages\flask\_compat.py", line 39, in reraise
    raise value
  File "C:\Users\dylmp\scoop\apps\python\current\lib\site-packages\flask\app.py", line 1947, in full_dispatch_request
    rv = self.preprocess_request()
  File "C:\Users\dylmp\scoop\apps\python\current\lib\site-packages\flask\app.py", line 2241, in preprocess_request
    rv = func()
  File "C:\Users\dylmp\CodeProjects\exampleblog\app\routes.py", line 91, in before_request
    g.locale = str(get_locale())
  File "C:\Users\dylmp\scoop\apps\python\current\lib\site-packages\flask_babel\__init__.py", line 257, in get_locale
    rv = babel.locale_selector_func()
  File "C:\Users\dylmp\CodeProjects\exampleblog\app\__init__.py", line 59, in get_locale
    return request.accept_languages.best_match(app.config['LANGUAGES'])
NameError: name 'request' is not defined
2019-12-10 12:54:37,946 INFO: Microblog startup [in C:\Users\dylmp\CodeProjects\exampleblog\app\__init__.py:55]
2019-12-10 12:54:49,579 ERROR: Exception on /index [GET] [in C:\Users\dylmp\scoop\apps\python\current\lib\site-packages\flask\app.py:1890]
Traceback (most recent call last):
  File "C:\Users\dylmp\scoop\apps\python\current\lib\site-packages\flask\app.py", line 2446, in wsgi_app
    response = self.full_dispatch_request()
  File "C:\Users\dylmp\scoop\apps\python\current\lib\site-packages\flask\app.py", line 1951, in full_dispatch_request
    rv = self.handle_user_exception(e)
  File "C:\Users\dylmp\scoop\apps\python\current\lib\site-packages\flask\app.py", line 1820, in handle_user_exception
    reraise(exc_type, exc_value, tb)
  File "C:\Users\dylmp\scoop\apps\python\current\lib\site-packages\flask\_compat.py", line 39, in reraise
    raise value
  File "C:\Users\dylmp\scoop\apps\python\current\lib\site-packages\flask\app.py", line 1949, in full_dispatch_request
    rv = self.dispatch_request()
  File "C:\Users\dylmp\scoop\apps\python\current\lib\site-packages\flask\app.py", line 1935, in dispatch_request
    return self.view_functions[rule.endpoint](**req.view_args)
  File "C:\Users\dylmp\scoop\apps\python\current\lib\site-packages\flask_login\utils.py", line 261, in decorated_view
    return func(*args, **kwargs)
  File "C:\Users\dylmp\CodeProjects\exampleblog\app\routes.py", line 16, in index
    search = SearchForm(request.form)
  File "C:\Users\dylmp\scoop\apps\python\current\lib\site-packages\wtforms\form.py", line 212, in __call__
    return type.__call__(cls, *args, **kwargs)
  File "C:\Users\dylmp\CodeProjects\exampleblog\app\forms.py", line 69, in __init__
    super(SearchForm, self).__init__(*args, **kwargs)
TypeError: __init__() got multiple values for argument 'formdata'
2019-12-10 12:56:52,213 INFO: Microblog startup [in C:\Users\dylmp\CodeProjects\exampleblog\app\__init__.py:55]
